Workbook
Name p3341_48900: '2026'!$F$1427
Name p2311_48900: '2026'!$F$1405
Name p4320_46700: '2026'!$F$1448
Name p3260_48900: '2026'!$F$1415
Name p1610_48900: '2026'!$F$1393
Name suma_cap5: '2026'!$F$1483
Name suma_cap9: '2026'!$F$1717
Name suma_cap2: '2026'!$F$1371
Name p3380_48900: '2026'!$F$1435
Name suma_cap4: '2026'!$F$1473
Name p9430_48900: '2026'!$F$1470
Name p3262_48900: '2026'!$F$1419
Name p9240_48900: '2026'!$F$1466
Name p2311_48901: '2026'!$F$1406
Name p4330_47900: '2026'!$F$1453
Name suma_cap1: '2026'!$F$508
Name p4320_48900: '2026'!$F$1449
Name P3360_78000: '2026'!$F$1694
Name p1700_48900: '2026'!$F$1397
Name p4310_48900: '2026'!$F$1444
Name suma_cap3: '2026'!$F$1386
Name suma_cap6: '2026'!$F$1682
Name p9200_48900: '2026'!$F$1462
Name p3340_48900: '2026'!$F$1423
Name p1710_48900: '2026'!$F$1401
Name p1522_78000: '2026'!$F$1689
Name suma_cap8: '2026'!$F$1707
Name p1522_78001: '2026'!$F$1690
Name p2313_48900: '2026'!$F$1411
Name p3373_48900: '2026'!$F$1431
Name p3410_48900: '2026'!$F$1439
Name p2311_48902: '2026'!$F$1407
Name p4330_48900: '2026'!$F$1454
Name suma_cap7: '2026'!$F$1697
Name p9120_48900: '2026'!$F$1458

Sheet 2026
G1: =IFERROR(((E1-#REF!)/#REF!), "")
G2: =IFERROR(((E2-#REF!)/#REF!), "")
B3: CLASIFICACIÓN | D3: CAPÍTULO I | G3: =IFERROR(((E3-#REF!)/#REF!), "")
B4: PROGRAMA | C4: ECONÓMICA | G4: =IFERROR(((E4-#REF!)/#REF!), "")
B5: 1300 | D5: ADMON. GRAL. DE LA SEGURIDAD | E5: 2025 | F5: 2026 | G5: =IFERROR(((F5-E5)/E5), "") -> 0.00049382716
C6: 120.03 | D6: Sueldos del Grupo C1 | E6: 29000 | F6: 29000 | G6: =IFERROR(((F6-E6)/E6), "") -> 0
C7: 120.04 | D7: Sueldos del Grupo C2 | E7: 25000 | F7: 25000 | G7: =IFERROR(((F7-E7)/E7), "") -> 0
C8: 120.06 | D8: Trienios | E8: 6775 | F8: 6775 | G8: =IFERROR(((F8-E8)/E8), "") -> 0
C9: 121.00 | D9: Complemento de destino | E9: 21150 | F9: 21150 | G9: =IFERROR(((F9-E9)/E9), "") -> 0
C10: 121.01 | D10: Complemento específico | E10: 28150 | F10: 28150 | G10: =IFERROR(((F10-E10)/E10), "") -> 0
C11: 150 | D11: Productividad | E11: 2800 | F11: 2800 | G11: =IFERROR(((F11-E11)/E11), "") -> 0
C12: 160.00 | D12: Cuotas Seguridad Social | E12: 33500 | F12: 33500 | G12: =IFERROR(((F12-E12)/E12), "") -> 0
C13: 131.00 | D13: Retribuciones básicas | E13: 18500 | F13: 18500 | G13: =IFERROR(((F13-E13)/E13), "") -> 0
C14: 131.02 | D14: Otras remuneraciones | E14: 5500 | F14: 5500 | G14: =IFERROR(((F14-E14)/E14), "") -> 0
C15: 160.02 | D15: Cuotas Seguridad Social | E15: 6800 | F15: 6800 | G15: =IFERROR(((F15-E15)/E15), "") -> 0
D16: 1300 | E16: 177175 | F16: =SUM(F6:F15) -> 177175 | G16: =IFERROR(((F16-E16)/E16), "") -> 0
G17: =IFERROR(((F17-E17)/E17), "")
B18: 1320 | D18: SEGURIDAD | E18: 2025 | F18: 2026 | G18: =IFERROR(((F18-E18)/E18), "") -> 0.00049382716
C19: 120.01 | D19: Sueldos del Grupo A2 | E19: 20100 | F19: 20100 | G19: =IFERROR(((F19-E19)/E19), "") -> 0
C20: 120.03 | D20: Sueldos del Grupo C1 | E20: 701000 | F20: 701000 | G20: =IFERROR(((F20-E20)/E20), "") -> 0
C21: 120.06 | D21: Trienios | E21: 55500 | F21: 55500 | G21: =IFERROR(((F21-E21)/E21), "") -> 0
C22: 121.00 | D22: Complemento de destino | E22: 232000 | F22: 232000 | G22: =IFERROR(((F22-E22)/E22), "") -> 0
C23: 121.01 | D23: Complemento específico | E23: 446000 | F23: 446000 | G23: =IFERROR(((F23-E23)/E23), "") -> 0
C24: 150 | D24: Productividad | E24: 132000 | F24: 132000 | G24: =IFERROR(((F24-E24)/E24), "") -> 0
C25: 151.00 | D25: Gratificaciones | E25: 310000 | F25: 310000 | G25: =IFERROR(((F25-E25)/E25), "") -> 0
C26: 160.00 | D26: Cuotas Seguridad Social | E26: 598000 | F26: 598000 | G26: =IFERROR(((F26-E26)/E26), "") -> 0
D27: 1320 | E27: 2494600 | F27: =SUM(F19:F26) -> 2494600 | G27: =IFERROR(((F27-E27)/E27), "") -> 0
G28: =IFERROR(((F28-E28)/E28), "")
B29: 1360 | D29: EXTINCIÓN DE INCENDIOS | E29: 2025 | F29: 2026 | G29: =IFERROR(((F29-E29)/E29), "") -> 0.00049382716
C30: 120.00 | D30: Sueldos del Grupo A1 | E30: 21500 | F30: 21500 | G30: =IFERROR(((F30-E30)/E30), "") -> 0
C31: 120.01 | D31: Sueldos del Grupo A2 | E31: 0 | F31: 0 | G31: =IFERROR(((F31-E31)/E31), "")
C32: 120.03 | D32: Sueldos del Grupo C1 | E32: 341000 | F32: 341000 | G32: =IFERROR(((F32-E32)/E32), "") -> 0
C33: 120.04 | D33: Sueldos del Grupo C2 | E33: 0 | F33: 0 | G33: =IFERROR(((F33-E33)/E33), "")
C34: 120.06 | D34: Trienios | E34: 68000 | F34: 68000 | G34: =IFERROR(((F34-E34)/E34), "") -> 0
C35: 121.00 | D35: Complemento de destino | E35: 155000 | F35: 155000 | G35: =IFERROR(((F35-E35)/E35), "") -> 0
C36: 121.01 | D36: Complemento específico | E36: 256000 | F36: 256000 | G36: =IFERROR(((F36-E36)/E36), "") -> 0
C37: 150 | D37: Productividad | E37: 400000 | F37: 400000 | G37: =IFERROR(((F37-E37)/E37), "") -> 0
C38: 151.00 | D38: Gratificaciones | E38: 300000 | F38: 300000 | G38: =IFERROR(((F38-E38)/E38), "") -> 0
C39: 160.00 | D39: Cuotas Seguridad Social | E39: 386000 | F39: 386000 | G39: =IFERROR(((F39-E39)/E39), "") -> 0
B40: 1360 | E40: 1927500 | F40: =SUM(F30:F39) -> 1927500 | G40: =IFERROR(((F40-E40)/E40), "") -> 0
...

Sheet Liberaciones & Libre desig
C2: Dedic. excl. | D2: Eventuales | I2: Salario | J2: SS | K2: Ded.exc. idmn. máx | L2: TOTAL
B3: Número | C3: 4 | D3: 2 | F3: 4+3 | H3: COSTE DEDIC. EXCL | I3: =C4 * C3 -> 168000 | J3: =(C4*0.3) * C3 -> 50400 | K3: =1380 * 12 * C3 -> 66240 | L3: =SUM(I3:J3) - K3 -> 152160
B4: Coste | C4: 42000 | D4: 35000 | F4: 332320 | H4: COSTE EVENTUALES | I4: =D4 * D3 -> 70000 | J4: =(D4*0.3) * D3 -> 21000 | K4: 0 | L4: =SUM(I4:K4) -> 91000
K5: TOTAL | L5: =SUM(L3:L4) -> 243160
